<?xml version="1.0" ?>
<!-- =================================================================================== -->
<!-- |    This document was autogenerated by xacro from arm.urdf.xacro                 | -->
<!-- |    EDITING THIS FILE BY HAND IS NOT RECOMMENDED                                 | -->
<!-- =================================================================================== -->
<robot name="arm">
  <link name="base_link">
    <visual>
      <geometry>
        <mesh filename="package://arm_description/meshes/base_link.stl" scale="0.001 0.001 0.001"/>
      </geometry>
      <origin rpy="0 0 0" xyz="0 0 0"/>
    </visual>
    <collision>
      <geometry>
        <box size="0.09 0.09 0.09"/>
      </geometry>
      <origin rpy="0 0 0" xyz="0 0 0"/>
    </collision>
    <inertial>
      <mass value="0.1"/>
      <inertia ixx="1.06682889e+08" ixy="0.0" ixz="0.0" iyy="9.92165844e+07" iyz="0.0" izz="1.26939175e+08"/>
    </inertial>
  </link>
  <joint name="base_1_2" type="fixed">
    <parent link="base_link"/>
    <child link="base_turn"/>
    <origin xyz="-0.0011 -0.011 0.05"/>
  </joint>
  <link name="base_turn">
    <visual>
      <geometry>
        <mesh filename="package://arm_description/meshes/base_turn.stl" scale="0.001 0.001 0.001"/>
      </geometry>
      <origin rpy="0 0 0" xyz="0 0 0"/>
    </visual>
    <collision>
      <geometry>
        <box size="0.08 0.08 0.01"/>
      </geometry>
      <origin rpy="0 0 0" xyz="0 0.01 0"/>
    </collision>
    <inertial>
      <mass value="0.1"/>
      <inertia ixx="1.35223008e+07" ixy="0.0" ixz="0.0" iyy="8.13814925e+06" iyz="0.0" izz="2.14903814e+07"/>
    </inertial>
  </link>
  <joint name="j0" type="revolute">
    <parent link="base_turn"/>
    <child link="base_turn_rot"/>
    <origin rpy="0 0 -1.57" xyz="-0.0 0.0155 0.013"/>
    <axis xyz="0 0 1"/>
    <limit effort="300" lower="-2.57" upper="2.57" velocity="0.1"/>
  </joint>
  <link name="base_turn_rot">
    <visual>
      <geometry>
        <mesh filename="package://arm_description/meshes/base_turn_table_rot.stl" scale="0.001 0.001 0.001"/>
      </geometry>
    </visual>
    <collision>
      <geometry>
        <box size="0.06 0.06 0.021"/>
      </geometry>
      <origin rpy="0 0 0" xyz="0 0 0"/>
    </collision>
    <inertial>
      <mass value="0.1"/>
      <inertia ixx="3.41992001e+06" ixy="0.0" ixz="0.0" iyy="2.85587836e+06" iyz="0.0" izz="5.84313870e+06"/>
    </inertial>
  </link>
  <joint name="base_turn_rot_dyn2" type="fixed">
    <parent link="base_turn_rot"/>
    <child link="dyn2"/>
    <origin rpy="0 1.57 1.57 " xyz="0 0 0.0385"/>
  </joint>
  <link name="dyn2">
    <visual>
      <geometry>
        <mesh filename="package://arm_description/meshes/dyn.stl" scale="0.01 0.01 0.01"/>
      </geometry>
      <origin rpy="0 0 0" xyz="0 0 0"/>
    </visual>
    <collision>
      <geometry>
        <box size="0.05 0.05 0.05"/>
      </geometry>
      <origin rpy="0 0 0" xyz="0.01 0 0"/>
    </collision>
    <inertial>
      <mass value="0.1"/>
      <inertia ixx="6.90013881e+01" ixy="0.0" ixz="0.0" iyy="1.24554875e+02" iyz="0.0" izz="1.04295793e+02"/>
    </inertial>
  </link>
  <joint name="j1" type="revolute">
    <parent link="dyn2"/>
    <child link="dyn2_r"/>
    <origin rpy="0 0 0" xyz="0 0 0.0"/>
    <axis xyz="0 0 1"/>
    <limit effort="300" lower="-3.14" upper="3.14" velocity="0.1"/>
  </joint>
  <link name="dyn2_r">
    
  </link>
  <joint name="dyn2_f4" type="fixed">
    <parent link="dyn2_r"/>
    <child link="f4"/>
    <origin rpy="0 1.57 1.57" xyz="-0.047 0.0 -0.003"/>
  </joint>
  <link name="f4">
    <visual>
      <geometry>
        <mesh filename="package://arm_description/meshes/f4_n_f3.stl" scale="0.001 0.001 0.001"/>
      </geometry>
      <origin rpy="0 0 0" xyz="0 0 0"/>
      <material name="white">
        <color rgba="1 1 1 1"/>
      </material>
    </visual>
    <collision>
      <geometry>
        <box size="0.05 0.1 0.03"/>
      </geometry>
      <origin rpy="0 0 0" xyz="-0.005 -0.01 0"/>
    </collision>
    <inertial>
      <mass value="0.1"/>
      <inertia ixx="6.90013881e+01" ixy="0.0" ixz="0.0" iyy="1.24554875e+02" iyz="0.0" izz="1.04295793e+02"/>
    </inertial>
  </link>
  <joint name="d4_dyn3" type="fixed">
    <parent link="f4"/>
    <child link="dyn3"/>
    <origin rpy="-1.57 3.14 1.57" xyz="-0.004 0.0645 0 "/>
  </joint>
  <link name="dyn3">
    <visual>
      <geometry>
        <mesh filename="package://arm_description/meshes/dyn.stl" scale="0.01 0.01 0.01"/>
      </geometry>
      <origin rpy="0 0 0" xyz="0 0 0"/>
    </visual>
    <collision>
      <geometry>
        <box size="0.05 0.05 0.05"/>
      </geometry>
      <origin rpy="0 0 0" xyz="0.01 0 0"/>
    </collision>
    <inertial>
      <mass value="0.1"/>
      <inertia ixx="6.90013881e+01" ixy="0.0" ixz="0.0" iyy="1.24554875e+02" iyz="0.0" izz="1.04295793e+02"/>
    </inertial>
  </link>
  <joint name="j2" type="revolute">
    <parent link="dyn3"/>
    <child link="dyn3_r"/>
    <origin rpy="0 0 0" xyz="0 0 0.0"/>
    <axis xyz="0 0 1"/>
    <limit effort="300" lower="-3.14" upper="3.14" velocity="0.1"/>
  </joint>
  <link name="dyn3_r">
    
  </link>
  <joint name="dyn3_f5" type="fixed">
    <parent link="dyn3_r"/>
    <child link="f5"/>
    <origin rpy="1.57 1.57 3.1415 " xyz="-0.046 -0.0 -0.002"/>
  </joint>
  <link name="f5">
    <visual>
      <geometry>
        <mesh filename="package://arm_description/meshes/f4_n_f3.stl" scale="0.001 0.001 0.001"/>
      </geometry>
      <origin rpy="0 0 0" xyz="0 0 0"/>
      <material name="white">
        <color rgba="1 1 1 1"/>
      </material>
    </visual>
    <collision>
      <geometry>
        <box size="0.05 0.1 0.03"/>
      </geometry>
      <origin rpy="0 0 0" xyz="-0.005 -0.01 0"/>
    </collision>
    <inertial>
      <mass value="0.1"/>
      <inertia ixx="1.13130695e+07" ixy="0.0" ixz="0.0" iyy="8.78052401e+06" iyz="0.0" izz="1.72940286e+07"/>
    </inertial>
  </link>
  <joint name="f5_dyn4" type="fixed">
    <parent link="f5"/>
    <child link="dyn4"/>
    <origin rpy="-1.57 3.1415 1.57 " xyz="-0.004 0.065 -0.0"/>
  </joint>
  <link name="dyn4">
    <visual>
      <geometry>
        <mesh filename="package://arm_description/meshes/dyn.stl" scale="0.01 0.01 0.01"/>
      </geometry>
      <origin rpy="0 0 0" xyz="0 0 0"/>
    </visual>
    <collision>
      <geometry>
        <box size="0.05 0.05 0.05"/>
      </geometry>
      <origin rpy="0 0 0" xyz="0.01 0 0"/>
    </collision>
    <inertial>
      <mass value="0.1"/>
      <inertia ixx="6.90013881e+01" ixy="0.0" ixz="0.0" iyy="1.24554875e+02" iyz="0.0" izz="1.04295793e+02"/>
    </inertial>
  </link>
  <joint name="j3" type="revolute">
    <parent link="dyn4"/>
    <child link="dyn4_r"/>
    <origin rpy="0 0 0" xyz="0 0 0.0"/>
    <axis xyz="0 0 1"/>
    <limit effort="300" lower="-3.14" upper="3.14" velocity="0.1"/>
  </joint>
  <link name="dyn4_r">
    
  </link>
  <joint name="f5_wrist" type="fixed">
    <parent link="dyn4_r"/>
    <child link="wrist"/>
    <origin rpy="1.57 1.57 -1.57" xyz="-0.017 -0.013 0.003"/>
  </joint>
  <link name="wrist">
    <visual>
      <geometry>
        <mesh filename="package://arm_description/meshes/wrist.stl" scale="0.001 0.001 0.001"/>
      </geometry>
      <origin rpy="0 0 0" xyz="0 0 0"/>
      <material name="white">
        <color rgba="1 1 1 1"/>
      </material>
    </visual>
    <collision>
      <geometry>
        <box size="0.05 0.06 0.05"/>
      </geometry>
      <origin rpy="0 0 0" xyz="0 0 0"/>
    </collision>
    <inertial>
      <mass value="0.1"/>
      <inertia ixx="6.90013881e+01" ixy="0.0" ixz="0.0" iyy="1.24554875e+02" iyz="0.0" izz="1.04295793e+02"/>
    </inertial>
  </link>
  <joint name="wrist_dyn5" type="fixed">
    <parent link="wrist"/>
    <child link="dyn5"/>
    <origin rpy="0 0 1.57" xyz="0.0038 -0.013 0.0275"/>
  </joint>
  <link name="dyn5">
    <visual>
      <geometry>
        <mesh filename="package://arm_description/meshes/dyn.stl" scale="0.01 0.01 0.01"/>
      </geometry>
      <origin rpy="0 0 0" xyz="0 0 0"/>
    </visual>
    <collision>
      <geometry>
        <box size="0.05 0.05 0.05"/>
      </geometry>
      <origin rpy="0 0 0" xyz="0.01 0 0"/>
    </collision>
    <inertial>
      <mass value="0.1"/>
      <inertia ixx="6.90013881e+01" ixy="0.0" ixz="0.0" iyy="1.24554875e+02" iyz="0.0" izz="1.04295793e+02"/>
    </inertial>
  </link>
  <joint name="dyn5_dyn5_r" type="fixed">
    <parent link="dyn5"/>
    <child link="dyn5_r"/>
    <origin rpy="0 0 0" xyz="0 0 0.0"/>
    <axis xyz="0 0 1"/>
    <limit effort="300" lower="-3.14" upper="3.14" velocity="0.1"/>
  </joint>
  <link name="dyn5_r">
    
  </link>
  <joint name="wrist_rotate_dyn5" type="fixed">
    <parent link="dyn5_r"/>
    <child link="crawer_base"/>
    <origin rpy="0 0 1.57" xyz="0.015 0 0.019"/>
  </joint>
  <link name="crawer_base">
    <visual>
      <geometry>
        <mesh filename="package://arm_description/meshes/the_crawer_base.stl" scale="0.001 0.001 0.001"/>
      </geometry>
      <origin rpy="0 0 0" xyz="0 0 0"/>
      <material name="white">
        <color rgba="1 1 1 1"/>
      </material>
    </visual>
    <collision>
      <geometry>
        <box size="0.11 0.05 0.005"/>
      </geometry>
      <origin rpy="0 0 0" xyz="0 0 0"/>
    </collision>
    <inertial>
      <mass value="0.1"/>
      <inertia ixx="6.90013881e+01" ixy="0.0" ixz="0.0" iyy="1.24554875e+02" iyz="0.0" izz="1.04295793e+02"/>
    </inertial>
  </link>
  <joint name="crawer_base_crawer_left" type="fixed">
    <parent link="crawer_base"/>
    <child link="crawer_left"/>
    <origin rpy="0 -1.57 0" xyz="-0.03 0.015 0.01"/>
  </joint>
  <link name="crawer_left">
    <visual>
      <geometry>
        <mesh filename="package://arm_description/meshes/the_crawer.stl" scale="0.001 0.001 0.001"/>
      </geometry>
      <origin rpy="0 0 0" xyz="0 0 0"/>
      <material name="white">
        <color rgba="1 1 1 1"/>
      </material>
    </visual>
    <collision>
      <geometry>
        <box size="0.07 0.04 0.05"/>
      </geometry>
      <origin rpy="0 0 0" xyz="0.02 0 0.01"/>
    </collision>
    <inertial>
      <mass value="0.1"/>
      <inertia ixx="6.90013881e+01" ixy="0.0" ixz="0.0" iyy="1.24554875e+02" iyz="0.0" izz="1.04295793e+02"/>
    </inertial>
  </link>
  <joint name="crawer_base_crawer_right" type="fixed">
    <parent link="crawer_base"/>
    <child link="crawer_right"/>
    <origin rpy="3.1415 -1.57 0" xyz="0.03 0.015 0.01"/>
  </joint>
  <link name="crawer_right">
    <visual>
      <geometry>
        <mesh filename="package://arm_description/meshes/the_crawer.stl" scale="0.001 0.001 0.001"/>
      </geometry>
      <origin rpy="0 0 0" xyz="0 0 0"/>
      <material name="white">
        <color rgba="1 1 1 1"/>
      </material>
    </visual>
    <collision>
      <geometry>
        <box size="0.07 0.04 0.05"/>
      </geometry>
      <origin rpy="0 0 0" xyz="0.02 0 0.01"/>
    </collision>
    <inertial>
      <mass value="0.1"/>
      <inertia ixx="6.90013881e+01" ixy="0.0" ixz="0.0" iyy="1.24554875e+02" iyz="0.0" izz="1.04295793e+02"/>
    </inertial>
  </link>
  <!-- Enable the Joint Feedback -->
  <!--<gazebo reference="${robot_name}_joint_7">
      <provideFeedback>true</provideFeedback>
    </gazebo> -->
  <!-- The ft_sensor plugin -->
  <!-- <gazebo>
      <plugin name="ft_sensor" filename="libgazebo_ros_ft_sensor.so">
        <updateRate>50.0</updateRate>
        <topicName>/${robot_name}/state/CartesianWrench</topicName>
        <jointName>${robot_name}_joint_7</jointName>
      </plugin>
    </gazebo>    -->
  <!-- Load Gazebo lib and set the robot namespace -->
  <gazebo>
    <plugin filename="libgazebo_ros_control.so" name="gazebo_ros_control">
      <robotNamespace>/arm</robotNamespace>
    </plugin>
  </gazebo>
  <gazebo reference="f4">
    <material>Gazebo/Red</material>
  </gazebo>
  <gazebo reference="f5">
    <material>Gazebo/Red</material>
  </gazebo>
  <gazebo reference="wrist">
    <material>Gazebo/Red</material>
  </gazebo>
  <gazebo reference="crawer_base">
    <material>Gazebo/Red</material>
  </gazebo>
  <gazebo reference="base_link">
    <material>Gazebo/Red</material>
  </gazebo>
  <gazebo reference="base_turn">
    <material>Gazebo/Red</material>
  </gazebo>
  <gazebo reference="base_turn_rot">
    <material>Gazebo/Red</material>
  </gazebo>
  <gazebo reference="dyn2">
    <material>Gazebo/Black</material>
  </gazebo>
  <gazebo reference="dyn3">
    <material>Gazebo/Black</material>
  </gazebo>
  <gazebo reference="dyn4">
    <material>Gazebo/Black</material>
  </gazebo>
  <gazebo reference="dyn5">
    <material>Gazebo/Black</material>
  </gazebo>
  <gazebo reference="crawer_left">
    <material>Gazebo/Red</material>
  </gazebo>
  <gazebo reference="crawer_right">
    <material>Gazebo/Red</material>
  </gazebo>
  <transmission name="arm_tran_0">
    <robotNamespace>/arm</robotNamespace>
    <type>transmission_interface/SimpleTransmission</type>
    <joint name="j0">
      <hardwareInterface>hardware_interface/PositionJointInterface</hardwareInterface>
    </joint>
    <actuator name="arm_motor_0">
      <hardwareInterface>hardware_interface/PositionJointInterface</hardwareInterface>
      <mechanicalReduction>1</mechanicalReduction>
    </actuator>
  </transmission>
  <transmission name="arm_tran_1">
    <robotNamespace>/arm</robotNamespace>
    <type>transmission_interface/SimpleTransmission</type>
    <joint name="j1">
      <hardwareInterface>hardware_interface/PositionJointInterface</hardwareInterface>
    </joint>
    <actuator name="arm_motor_1">
      <hardwareInterface>hardware_interface/PositionJointInterface</hardwareInterface>
      <mechanicalReduction>1</mechanicalReduction>
    </actuator>
  </transmission>
  <transmission name="arm_tran_2">
    <robotNamespace>/arm</robotNamespace>
    <type>transmission_interface/SimpleTransmission</type>
    <joint name="j2">
      <hardwareInterface>hardware_interface/PositionJointInterface</hardwareInterface>
    </joint>
    <actuator name="arm_motor_2">
      <hardwareInterface>hardware_interface/PositionJointInterface</hardwareInterface>
      <mechanicalReduction>1</mechanicalReduction>
    </actuator>
  </transmission>
  <transmission name="arm_tran_3">
    <robotNamespace>/arm</robotNamespace>
    <type>transmission_interface/SimpleTransmission</type>
    <joint name="j3">
      <hardwareInterface>hardware_interface/PositionJointInterface</hardwareInterface>
    </joint>
    <actuator name="arm_motor_3">
      <hardwareInterface>hardware_interface/PositionJointInterface</hardwareInterface>
      <mechanicalReduction>1</mechanicalReduction>
    </actuator>
  </transmission>
  <!-- <transmission name="$(arg robot_name)_tran_5">
      <robotNamespace>/$(arg robot_name)</robotNamespace>
      <type>transmission_interface/SimpleTransmission</type>
      <joint name="$(arg robot_name)_joint_5">
        <hardwareInterface>hardware_interface/$(arg hardware_interface)</hardwareInterface>
      </joint>
      <actuator name="$(arg robot_name)_motor_5">
        <hardwareInterface>hardware_interface/$(arg hardware_interface)</hardwareInterface>
        <mechanicalReduction>1</mechanicalReduction>
      </actuator>
    </transmission>

    <transmission name="$(arg robot_name)_tran_6">
      <robotNamespace>/$(arg robot_name)</robotNamespace>
      <type>transmission_interface/SimpleTransmission</type>
      <joint name="$(arg robot_name)_joint_6">
        <hardwareInterface>hardware_interface/$(arg hardware_interface)</hardwareInterface>
      </joint>
      <actuator name="$(arg robot_name)_motor_6">
        <hardwareInterface>hardware_interface/$(arg hardware_interface)</hardwareInterface>
        <mechanicalReduction>1</mechanicalReduction>
      </actuator>
    </transmission>

    <transmission name="$(arg robot_name)_tran_7">
      <robotNamespace>/$(arg robot_name)</robotNamespace>
      <type>transmission_interface/SimpleTransmission</type>
      <joint name="$(arg robot_name)_joint_7">
        <hardwareInterface>hardware_interface/$(arg hardware_interface)</hardwareInterface>
      </joint>
      <actuator name="$(arg robot_name)_motor_7">
        <hardwareInterface>hardware_interface/$(arg hardware_interface)</hardwareInterface>
        <mechanicalReduction>1</mechanicalReduction>
      </actuator>
    </transmission> -->
</robot>

